[2024-08-01T19:32:04.581+0700] {local_task_job_runner.py:120} INFO - ::group::Pre task execution logs
[2024-08-01T19:32:04.597+0700] {taskinstance.py:2076} INFO - Dependencies all met for dep_context=non-requeueable deps ti=<TaskInstance: postgres_test.create_table manual__2024-08-01T12:32:01.990295+00:00 [queued]>
[2024-08-01T19:32:04.604+0700] {taskinstance.py:2076} INFO - Dependencies all met for dep_context=requeueable deps ti=<TaskInstance: postgres_test.create_table manual__2024-08-01T12:32:01.990295+00:00 [queued]>
[2024-08-01T19:32:04.604+0700] {taskinstance.py:2306} INFO - Starting attempt 1 of 1
[2024-08-01T19:32:04.629+0700] {taskinstance.py:2330} INFO - Executing <Task(PostgresOperator): create_table> on 2024-08-01 12:32:01.990295+00:00
[2024-08-01T19:32:04.631+0700] {standard_task_runner.py:64} INFO - Started process 10601 to run task
[2024-08-01T19:32:04.633+0700] {standard_task_runner.py:90} INFO - Running: ['airflow', 'tasks', 'run', 'postgres_test', 'create_table', 'manual__2024-08-01T12:32:01.990295+00:00', '--job-id', '69', '--raw', '--subdir', 'DAGS_FOLDER/postgres_test.py', '--cfg-path', '/tmp/tmpq44_kvbi']
[2024-08-01T19:32:04.634+0700] {standard_task_runner.py:91} INFO - Job 69: Subtask create_table
[2024-08-01T19:32:04.672+0700] {task_command.py:426} INFO - Running <TaskInstance: postgres_test.create_table manual__2024-08-01T12:32:01.990295+00:00 [running]> on host DESKTOP-RHVHV7A.
[2024-08-01T19:32:04.742+0700] {taskinstance.py:2648} INFO - Exporting env vars: AIRFLOW_CTX_DAG_OWNER='airflow' AIRFLOW_CTX_DAG_ID='postgres_test' AIRFLOW_CTX_TASK_ID='create_table' AIRFLOW_CTX_EXECUTION_DATE='2024-08-01T12:32:01.990295+00:00' AIRFLOW_CTX_TRY_NUMBER='1' AIRFLOW_CTX_DAG_RUN_ID='manual__2024-08-01T12:32:01.990295+00:00'
[2024-08-01T19:32:04.742+0700] {taskinstance.py:430} INFO - ::endgroup::
[2024-08-01T19:32:04.754+0700] {sql.py:282} INFO - Executing: 
    CREATE TABLE IF NOT EXISTS example_table (
        id SERIAL PRIMARY KEY,
        name VARCHAR(50) NOT NULL,
        created_at TIMESTAMP DEFAULT CURRENT_TIMESTAMP
    );
    
[2024-08-01T19:32:04.757+0700] {base.py:84} INFO - Using connection ID 'postgres_supermarket' for task execution.
[2024-08-01T19:32:04.775+0700] {base.py:84} INFO - Using connection ID 'postgres_supermarket' for task execution.
[2024-08-01T19:32:04.808+0700] {taskinstance.py:441} INFO - ::group::Post task execution logs
[2024-08-01T19:32:04.808+0700] {taskinstance.py:2905} ERROR - Task failed with exception
Traceback (most recent call last):
  File "/usr/local/lib/python3.10/dist-packages/airflow/models/taskinstance.py", line 465, in _execute_task
    result = _execute_callable(context=context, **execute_callable_kwargs)
  File "/usr/local/lib/python3.10/dist-packages/airflow/models/taskinstance.py", line 432, in _execute_callable
    return execute_callable(context=context, **execute_callable_kwargs)
  File "/usr/local/lib/python3.10/dist-packages/airflow/models/baseoperator.py", line 401, in wrapper
    return func(self, *args, **kwargs)
  File "/usr/local/lib/python3.10/dist-packages/airflow/providers/common/sql/operators/sql.py", line 288, in execute
    output = hook.run(
  File "/usr/local/lib/python3.10/dist-packages/airflow/providers/common/sql/hooks/sql.py", line 438, in run
    with self._create_autocommit_connection(autocommit) as conn:
  File "/usr/lib/python3.10/contextlib.py", line 135, in __enter__
    return next(self.gen)
  File "/usr/local/lib/python3.10/dist-packages/airflow/providers/common/sql/hooks/sql.py", line 560, in _create_autocommit_connection
    with closing(self.get_conn()) as conn:
  File "/usr/local/lib/python3.10/dist-packages/airflow/providers/postgres/hooks/postgres.py", line 175, in get_conn
    self.conn = psycopg2.connect(**conn_args)
  File "/usr/local/lib/python3.10/dist-packages/psycopg2/__init__.py", line 122, in connect
    conn = _connect(dsn, connection_factory=connection_factory, **kwasync)
psycopg2.OperationalError: connection to server at "192.168.1.11", port 5432 failed: FATAL:  database "supermarket.supermarket" does not exist

[2024-08-01T19:32:04.811+0700] {taskinstance.py:1206} INFO - Marking task as FAILED. dag_id=postgres_test, task_id=create_table, run_id=manual__2024-08-01T12:32:01.990295+00:00, execution_date=20240801T123201, start_date=20240801T123204, end_date=20240801T123204
[2024-08-01T19:32:04.833+0700] {standard_task_runner.py:110} ERROR - Failed to execute job 69 for task create_table (connection to server at "192.168.1.11", port 5432 failed: FATAL:  database "supermarket.supermarket" does not exist
; 10601)
[2024-08-01T19:32:04.846+0700] {local_task_job_runner.py:243} INFO - Task exited with return code 1
[2024-08-01T19:32:04.855+0700] {logging_mixin.py:188} WARNING - /usr/local/lib/python3.10/dist-packages/airflow/models/baseoperator.py:1297 AirflowProviderDeprecationWarning: Call to deprecated class PostgresOperator. (Please use `airflow.providers.common.sql.operators.sql.SQLExecuteQueryOperator`.Also, you can provide `hook_params={'schema': <database>}`.)
[2024-08-01T19:32:04.865+0700] {taskinstance.py:3503} INFO - 0 downstream tasks scheduled from follow-on schedule check
[2024-08-01T19:32:04.883+0700] {local_task_job_runner.py:222} INFO - ::endgroup::
