[2024-08-02T14:59:50.256+0700] {local_task_job_runner.py:120} INFO - ::group::Pre task execution logs
[2024-08-02T14:59:50.272+0700] {taskinstance.py:2076} INFO - Dependencies all met for dep_context=non-requeueable deps ti=<TaskInstance: data_pipeline_supermarket_2.airbyte_check_sync_0 manual__2024-08-02T07:55:35.133738+00:00 [queued]>
[2024-08-02T14:59:50.284+0700] {taskinstance.py:2076} INFO - Dependencies all met for dep_context=requeueable deps ti=<TaskInstance: data_pipeline_supermarket_2.airbyte_check_sync_0 manual__2024-08-02T07:55:35.133738+00:00 [queued]>
[2024-08-02T14:59:50.285+0700] {taskinstance.py:2306} INFO - Starting attempt 1 of 2
[2024-08-02T14:59:50.311+0700] {taskinstance.py:2330} INFO - Executing <Task(AirbyteJobSensor): airbyte_check_sync_0> on 2024-08-02 07:55:35.133738+00:00
[2024-08-02T14:59:50.315+0700] {standard_task_runner.py:64} INFO - Started process 23692 to run task
[2024-08-02T14:59:50.321+0700] {standard_task_runner.py:90} INFO - Running: ['airflow', 'tasks', 'run', 'data_pipeline_supermarket_2', 'airbyte_check_sync_0', 'manual__2024-08-02T07:55:35.133738+00:00', '--job-id', '148', '--raw', '--subdir', 'DAGS_FOLDER/data_pipeline_supermarket_2.py', '--cfg-path', '/tmp/tmpjnzuzd1f']
[2024-08-02T14:59:50.323+0700] {standard_task_runner.py:91} INFO - Job 148: Subtask airbyte_check_sync_0
[2024-08-02T14:59:50.371+0700] {task_command.py:426} INFO - Running <TaskInstance: data_pipeline_supermarket_2.airbyte_check_sync_0 manual__2024-08-02T07:55:35.133738+00:00 [running]> on host DESKTOP-RHVHV7A.
[2024-08-02T14:59:50.471+0700] {taskinstance.py:2648} INFO - Exporting env vars: AIRFLOW_CTX_DAG_OWNER='airflow' AIRFLOW_CTX_DAG_ID='data_pipeline_supermarket_2' AIRFLOW_CTX_TASK_ID='airbyte_check_sync_0' AIRFLOW_CTX_EXECUTION_DATE='2024-08-02T07:55:35.133738+00:00' AIRFLOW_CTX_TRY_NUMBER='1' AIRFLOW_CTX_DAG_RUN_ID='manual__2024-08-02T07:55:35.133738+00:00'
[2024-08-02T14:59:50.471+0700] {taskinstance.py:430} INFO - ::endgroup::
[2024-08-02T14:59:50.494+0700] {baseoperator.py:400} WARNING - AirbyteJobSensor.execute cannot be called outside TaskInstance!
[2024-08-02T14:59:50.501+0700] {base.py:84} INFO - Using connection ID 'airflow-call-to-airbyte-example' for task execution.
[2024-08-02T14:59:50.614+0700] {airbyte.py:113} INFO - Waiting for job 83 to complete.
[2024-08-02T14:59:59.229+0700] {local_task_job_runner.py:222} INFO - ::endgroup::
[2024-08-02T14:59:59.231+0700] {process_utils.py:132} INFO - Sending Signals.SIGTERM to group 23692. PIDs of all processes in the group: [23692]
[2024-08-02T14:59:59.232+0700] {process_utils.py:87} INFO - Sending the signal Signals.SIGTERM to group 23692
[2024-08-02T14:59:59.232+0700] {taskinstance.py:2611} ERROR - Received SIGTERM. Terminating subprocesses.
[2024-08-02T14:59:59.232+0700] {taskinstance.py:441} INFO - ::group::Post task execution logs
[2024-08-02T14:59:59.237+0700] {taskinstance.py:2905} ERROR - Task failed with exception
Traceback (most recent call last):
  File "/usr/local/lib/python3.10/dist-packages/airflow/models/taskinstance.py", line 465, in _execute_task
    result = _execute_callable(context=context, **execute_callable_kwargs)
  File "/usr/local/lib/python3.10/dist-packages/airflow/models/taskinstance.py", line 432, in _execute_callable
    return execute_callable(context=context, **execute_callable_kwargs)
  File "/usr/local/lib/python3.10/dist-packages/airflow/models/baseoperator.py", line 401, in wrapper
    return func(self, *args, **kwargs)
  File "/usr/local/lib/python3.10/dist-packages/airflow/providers/airbyte/sensors/airbyte.py", line 119, in execute
    super().execute(context)
  File "/usr/local/lib/python3.10/dist-packages/airflow/models/baseoperator.py", line 401, in wrapper
    return func(self, *args, **kwargs)
  File "/usr/local/lib/python3.10/dist-packages/airflow/sensors/base.py", line 292, in execute
    time.sleep(self._get_next_poke_interval(started_at, run_duration, poke_count))
  File "/usr/local/lib/python3.10/dist-packages/airflow/models/taskinstance.py", line 2613, in signal_handler
    raise AirflowTaskTerminated("Task received SIGTERM signal")
airflow.exceptions.AirflowTaskTerminated: Task received SIGTERM signal
[2024-08-02T14:59:59.241+0700] {taskinstance.py:1206} INFO - Marking task as UP_FOR_RETRY. dag_id=data_pipeline_supermarket_2, task_id=airbyte_check_sync_0, run_id=manual__2024-08-02T07:55:35.133738+00:00, execution_date=20240802T075535, start_date=20240802T075950, end_date=20240802T075959
