[2024-07-27T22:34:03.318+0700] {local_task_job_runner.py:120} INFO - ::group::Pre task execution logs
[2024-07-27T22:34:03.339+0700] {taskinstance.py:2076} INFO - Dependencies all met for dep_context=non-requeueable deps ti=<TaskInstance: example_postgres_dag.create_table manual__2024-07-27T15:33:59.363531+00:00 [queued]>
[2024-07-27T22:34:03.345+0700] {taskinstance.py:2076} INFO - Dependencies all met for dep_context=requeueable deps ti=<TaskInstance: example_postgres_dag.create_table manual__2024-07-27T15:33:59.363531+00:00 [queued]>
[2024-07-27T22:34:03.345+0700] {taskinstance.py:2306} INFO - Starting attempt 1 of 1
[2024-07-27T22:34:03.371+0700] {taskinstance.py:2330} INFO - Executing <Task(PostgresOperator): create_table> on 2024-07-27 15:33:59.363531+00:00
[2024-07-27T22:34:03.373+0700] {standard_task_runner.py:64} INFO - Started process 37777 to run task
[2024-07-27T22:34:03.377+0700] {standard_task_runner.py:90} INFO - Running: ['airflow', 'tasks', 'run', 'example_postgres_dag', 'create_table', 'manual__2024-07-27T15:33:59.363531+00:00', '--job-id', '12', '--raw', '--subdir', 'DAGS_FOLDER/example_postgres_dag.py.py', '--cfg-path', '/tmp/tmpsrg0w98g']
[2024-07-27T22:34:03.378+0700] {standard_task_runner.py:91} INFO - Job 12: Subtask create_table
[2024-07-27T22:34:03.434+0700] {task_command.py:426} INFO - Running <TaskInstance: example_postgres_dag.create_table manual__2024-07-27T15:33:59.363531+00:00 [running]> on host DESKTOP-RHVHV7A.
[2024-07-27T22:34:03.515+0700] {taskinstance.py:2648} INFO - Exporting env vars: AIRFLOW_CTX_DAG_OWNER='airflow' AIRFLOW_CTX_DAG_ID='example_postgres_dag' AIRFLOW_CTX_TASK_ID='create_table' AIRFLOW_CTX_EXECUTION_DATE='2024-07-27T15:33:59.363531+00:00' AIRFLOW_CTX_TRY_NUMBER='1' AIRFLOW_CTX_DAG_RUN_ID='manual__2024-07-27T15:33:59.363531+00:00'
[2024-07-27T22:34:03.516+0700] {taskinstance.py:430} INFO - ::endgroup::
[2024-07-27T22:34:03.534+0700] {sql.py:282} INFO - Executing: 
    CREATE TABLE IF NOT EXISTS example_table (
        id SERIAL PRIMARY KEY,
        name VARCHAR(50) NOT NULL,
        created_at TIMESTAMP DEFAULT CURRENT_TIMESTAMP
    );
    
[2024-07-27T22:34:03.540+0700] {base.py:84} INFO - Using connection ID 'postgres_default' for task execution.
[2024-07-27T22:34:03.580+0700] {base.py:84} INFO - Using connection ID 'postgres_default' for task execution.
[2024-07-27T22:35:33.952+0700] {local_task_job_runner.py:313} WARNING - State of this instance has been externally set to restarting. Terminating instance.
[2024-07-27T22:35:33.952+0700] {local_task_job_runner.py:222} INFO - ::endgroup::
[2024-07-27T22:35:33.953+0700] {process_utils.py:132} INFO - Sending Signals.SIGTERM to group 37777. PIDs of all processes in the group: [37777]
[2024-07-27T22:35:33.954+0700] {process_utils.py:87} INFO - Sending the signal Signals.SIGTERM to group 37777
[2024-07-27T22:36:14.546+0700] {taskinstance.py:2611} ERROR - Received SIGTERM. Terminating subprocesses.
[2024-07-27T22:36:14.547+0700] {taskinstance.py:441} INFO - ::group::Post task execution logs
[2024-07-27T22:36:14.551+0700] {taskinstance.py:2905} ERROR - Task failed with exception
Traceback (most recent call last):
  File "/usr/lib/python3.10/contextlib.py", line 135, in __enter__
    return next(self.gen)
  File "/usr/local/lib/python3.10/dist-packages/airflow/providers/common/sql/hooks/sql.py", line 560, in _create_autocommit_connection
    with closing(self.get_conn()) as conn:
  File "/usr/local/lib/python3.10/dist-packages/airflow/providers/postgres/hooks/postgres.py", line 175, in get_conn
    self.conn = psycopg2.connect(**conn_args)
  File "/usr/local/lib/python3.10/dist-packages/psycopg2/__init__.py", line 122, in connect
    conn = _connect(dsn, connection_factory=connection_factory, **kwasync)
psycopg2.OperationalError: connection to server at "192.168.144.1", port 5432 failed: Connection timed out
	Is the server running on that host and accepting TCP/IP connections?


During handling of the above exception, another exception occurred:

Traceback (most recent call last):
  File "/usr/local/lib/python3.10/dist-packages/airflow/models/taskinstance.py", line 465, in _execute_task
    result = _execute_callable(context=context, **execute_callable_kwargs)
  File "/usr/local/lib/python3.10/dist-packages/airflow/models/taskinstance.py", line 432, in _execute_callable
    return execute_callable(context=context, **execute_callable_kwargs)
  File "/usr/local/lib/python3.10/dist-packages/airflow/models/baseoperator.py", line 401, in wrapper
    return func(self, *args, **kwargs)
  File "/usr/local/lib/python3.10/dist-packages/airflow/providers/common/sql/operators/sql.py", line 288, in execute
    output = hook.run(
  File "/usr/local/lib/python3.10/dist-packages/airflow/providers/common/sql/hooks/sql.py", line 438, in run
    with self._create_autocommit_connection(autocommit) as conn:
  File "/usr/lib/python3.10/contextlib.py", line 135, in __enter__
    return next(self.gen)
  File "/usr/local/lib/python3.10/dist-packages/airflow/models/taskinstance.py", line 2613, in signal_handler
    raise AirflowTaskTerminated("Task received SIGTERM signal")
airflow.exceptions.AirflowTaskTerminated: Task received SIGTERM signal
[2024-07-27T22:36:14.557+0700] {taskinstance.py:1206} INFO - Marking task as UP_FOR_RETRY. dag_id=example_postgres_dag, task_id=create_table, run_id=manual__2024-07-27T15:33:59.363531+00:00, execution_date=20240727T153359, start_date=20240727T153403, end_date=20240727T153614
[2024-07-27T22:36:14.593+0700] {process_utils.py:80} INFO - Process psutil.Process(pid=37777, status='terminated', exitcode=2, started='22:34:02') (37777) terminated with exit code 2
