[2024-08-02T13:51:00.496+0700] {local_task_job_runner.py:120} INFO - ::group::Pre task execution logs
[2024-08-02T13:51:00.507+0700] {taskinstance.py:2076} INFO - Dependencies all met for dep_context=non-requeueable deps ti=<TaskInstance: data_pipeline_supermarket.airbyte_check_sync_2 scheduled__2024-08-01T00:00:00+00:00 [queued]>
[2024-08-02T13:51:00.515+0700] {taskinstance.py:2076} INFO - Dependencies all met for dep_context=requeueable deps ti=<TaskInstance: data_pipeline_supermarket.airbyte_check_sync_2 scheduled__2024-08-01T00:00:00+00:00 [queued]>
[2024-08-02T13:51:00.515+0700] {taskinstance.py:2306} INFO - Starting attempt 1 of 2
[2024-08-02T13:51:00.528+0700] {taskinstance.py:2330} INFO - Executing <Task(AirbyteJobSensor): airbyte_check_sync_2> on 2024-08-01 00:00:00+00:00
[2024-08-02T13:51:00.531+0700] {standard_task_runner.py:64} INFO - Started process 5875 to run task
[2024-08-02T13:51:00.534+0700] {standard_task_runner.py:90} INFO - Running: ['airflow', 'tasks', 'run', 'data_pipeline_supermarket', 'airbyte_check_sync_2', 'scheduled__2024-08-01T00:00:00+00:00', '--job-id', '98', '--raw', '--subdir', 'DAGS_FOLDER/data_pipeline_supermarket.py', '--cfg-path', '/tmp/tmpl0aovxrl']
[2024-08-02T13:51:00.535+0700] {standard_task_runner.py:91} INFO - Job 98: Subtask airbyte_check_sync_2
[2024-08-02T13:51:00.567+0700] {task_command.py:426} INFO - Running <TaskInstance: data_pipeline_supermarket.airbyte_check_sync_2 scheduled__2024-08-01T00:00:00+00:00 [running]> on host DESKTOP-RHVHV7A.
[2024-08-02T13:51:00.629+0700] {taskinstance.py:2648} INFO - Exporting env vars: AIRFLOW_CTX_DAG_OWNER='airflow' AIRFLOW_CTX_DAG_ID='data_pipeline_supermarket' AIRFLOW_CTX_TASK_ID='airbyte_check_sync_2' AIRFLOW_CTX_EXECUTION_DATE='2024-08-01T00:00:00+00:00' AIRFLOW_CTX_TRY_NUMBER='1' AIRFLOW_CTX_DAG_RUN_ID='scheduled__2024-08-01T00:00:00+00:00'
[2024-08-02T13:51:00.630+0700] {taskinstance.py:430} INFO - ::endgroup::
[2024-08-02T13:51:00.640+0700] {baseoperator.py:400} WARNING - AirbyteJobSensor.execute cannot be called outside TaskInstance!
[2024-08-02T13:51:00.645+0700] {base.py:84} INFO - Using connection ID 'airflow-call-to-airbyte-example' for task execution.
[2024-08-02T13:51:00.661+0700] {airbyte.py:113} INFO - Waiting for job 74 to complete.
[2024-08-02T13:51:56.135+0700] {local_task_job_runner.py:313} WARNING - State of this instance has been externally set to restarting. Terminating instance.
[2024-08-02T13:51:56.136+0700] {local_task_job_runner.py:222} INFO - ::endgroup::
[2024-08-02T13:51:56.137+0700] {process_utils.py:132} INFO - Sending Signals.SIGTERM to group 5875. PIDs of all processes in the group: [5875]
[2024-08-02T13:51:56.137+0700] {process_utils.py:87} INFO - Sending the signal Signals.SIGTERM to group 5875
[2024-08-02T13:51:56.138+0700] {taskinstance.py:2611} ERROR - Received SIGTERM. Terminating subprocesses.
[2024-08-02T13:51:56.139+0700] {taskinstance.py:441} INFO - ::group::Post task execution logs
[2024-08-02T13:51:56.143+0700] {taskinstance.py:2905} ERROR - Task failed with exception
Traceback (most recent call last):
  File "/usr/local/lib/python3.10/dist-packages/airflow/models/taskinstance.py", line 465, in _execute_task
    result = _execute_callable(context=context, **execute_callable_kwargs)
  File "/usr/local/lib/python3.10/dist-packages/airflow/models/taskinstance.py", line 432, in _execute_callable
    return execute_callable(context=context, **execute_callable_kwargs)
  File "/usr/local/lib/python3.10/dist-packages/airflow/models/baseoperator.py", line 401, in wrapper
    return func(self, *args, **kwargs)
  File "/usr/local/lib/python3.10/dist-packages/airflow/providers/airbyte/sensors/airbyte.py", line 119, in execute
    super().execute(context)
  File "/usr/local/lib/python3.10/dist-packages/airflow/models/baseoperator.py", line 401, in wrapper
    return func(self, *args, **kwargs)
  File "/usr/local/lib/python3.10/dist-packages/airflow/sensors/base.py", line 292, in execute
    time.sleep(self._get_next_poke_interval(started_at, run_duration, poke_count))
  File "/usr/local/lib/python3.10/dist-packages/airflow/models/taskinstance.py", line 2613, in signal_handler
    raise AirflowTaskTerminated("Task received SIGTERM signal")
airflow.exceptions.AirflowTaskTerminated: Task received SIGTERM signal
[2024-08-02T13:51:56.150+0700] {taskinstance.py:1206} INFO - Marking task as UP_FOR_RETRY. dag_id=data_pipeline_supermarket, task_id=airbyte_check_sync_2, run_id=scheduled__2024-08-01T00:00:00+00:00, execution_date=20240801T000000, start_date=20240802T065100, end_date=20240802T065156
[2024-08-02T13:51:56.190+0700] {process_utils.py:80} INFO - Process psutil.Process(pid=5875, status='terminated', exitcode=2, started='13:51:00') (5875) terminated with exit code 2
